<?xml version="1.0" ?>
<sdf version="1.8">
    <world name="world2">
        <physics name="1ms" type="ignored">
            <max_step_size>0.0001</max_step_size>
            <real_time_factor> 1</real_time_factor>
        </physics>
        <plugin filename="libignition-gazebo-physics-system.so" name="ignition::gazebo::systems::Physics">
        </plugin>
        <plugin filename="libignition-gazebo-user-commands-system.so" name="ignition::gazebo::systems::UserCommands">
        </plugin>
        <plugin filename="libignition-gazebo-scene-broadcaster-system.so" name="ignition::gazebo::systems::SceneBroadcaster">
        </plugin>
        <light type="directional" name="sun">
            <cast_shadows>true</cast_shadows>
            <pose>0 0 10 0 0 0</pose>
            <diffuse>0.8 0.8 0.8 1</diffuse>
            <specular>0.2 0.2 0.2 1</specular>
            <attenuation>
                <range>1000</range>
                <constant>0.9</constant>
                <linear>0.01</linear>
                <quadratic>0.001</quadratic>
            </attenuation>
            <direction>-0.5 0.1 -0.9</direction>
        </light>
        <model name="ground_plane">
            <pose relative_to="world">0 0 0 0 0 0</pose>
            <static>true</static>
            <link name="link">
                <collision name="link">
                    <geometry>
                        <plane>
                            <normal>0 0 1</normal>
                        </plane>
                    </geometry>
                </collision>
                <visual name="link">
                    <geometry>
                        <plane>
                            <normal>0 0 1</normal>
                            <size>100 100</size>
                        </plane>
                    </geometry>
                    <material>
                        <ambient>0.8 0.8 0.8 1</ambient>
                        <diffuse>0.8 0.8 0.8 1</diffuse>
                        <specular>0.8 0.8 0.8 1</specular>
                    </material>
                </visual>
            </link>
        </model>
        <model name="URDF_LargeWings">
            <pose relative_to="world">0 0 .5 1.5708 0 0</pose>
            <link name="body">
                <pose>0 0 0 0 0 0</pose>
                <inertial>
                    <pose>0 0 0 0 0 0</pose>
                    <mass>1.0</mass>
                    <inertia>
                        <ixx>0.1</ixx>
                        <ixy>0</ixy>
                        <ixz>0</ixz>
                        <iyy>0.1</iyy>
                        <iyz>0</iyz>
                        <izz>0.2</izz>
                    </inertia>
                </inertial>
                <visual name="body">
                    <pose>0 0 0 0 0 0</pose>
                    <geometry>
                        <box>
                            <size>0.025 0.025 0.01</size>
                        </box>
                    </geometry>
                    <material>
                        <ambient>0.0 0.0 1.0 1</ambient>
                        <diffuse>0.0 0.0 1.0 1</diffuse>
                        <specular>0.0 0.0 1.0 1</specular>
                    </material>
                </visual>
            </link>
            <link name="hinge">
                <pose relative_to="stroke_joint">0 0 0 0 0 0</pose>
                <inertial>
                    <mass>0.0057</mass>
                    <inertia>
                        <ixx>20.03e-9</ixx>
                        <ixy>-0.05e-9</ixy>
                        <ixz>4.55e-9</ixz>
                        <iyy>31.49e-9</iyy>
                        <iyz>0.02e-9</iyz>
                        <izz>11.75e-9</izz>
                    </inertia>
                </inertial>
                <visual name="hinge">
                    <pose relative_to="stroke_joint">0 0 0 0 0 0</pose>
                    <geometry>
                        <sphere>
                            <radius>0.0025</radius>
                        </sphere>
                    </geometry>
                    <material>
                        <ambient>1.0 0.0 1.0 .9</ambient>
                        <diffuse>1.0 0.0 1.0 .9</diffuse>
                        <specular>1.0 0.0 1.0 .9</specular>
                    </material>
                </visual>
            </link>
            <link name="wing">
                <pose relative_to="pitch_joint">0 0 0 0 0 0</pose>
                <inertial>
                    <pose>0.062210984952593716, 0, -0.0006656200549003314, 0, 0, 0</pose>
                    <mass>0.00034972566717007163</mass>
                    <inertia>
                        <ixx>8.6617921e-07</ixx>
                        <ixy>0.0</ixy>
                        <ixz>3.293019e-07</ixz>
                        <iyy>1.222500321e-06</iyy>
                        <iyz>0.0</iyz>
                        <izz>6.6904405e-07</izz>
                    </inertia>
                </inertial>
                <visual name="wing">
                    <pose relative_to="pitch_joint">0 0 0 0 0 0</pose>
                    <geometry>
                        <mesh>
                            <uri>model://URDF_LargeWings/meshes/RW_Pitch.STL</uri>
                        </mesh>
                    </geometry>
                    <material>
                        <ambient>1.0 0.0 0.0 .9</ambient>
                        <diffuse>1.0 0.0 0.0 .9</diffuse>
                        <specular>1.0 0.0 0.0 .9</specular>
                    </material>
                </visual>
                <collision name="wing">
                    <pose relative_to="pitch_joint">0 0 0 0 0 0</pose>
                    <geometry>
                        <mesh>
                            <uri>model://URDF_LargeWings/meshes/RW_Pitch.STL</uri>
                        </mesh>
                    </geometry>
                </collision>
            </link>
            <joint name="anchor2" type="revolute">
                <pose relative_to="body">0 0 0 0 0 0</pose>
                <parent>world</parent>
                <child>body</child>
                <axis>
                    <xyz>0 1 0</xyz>
                    <limit>
                        <effort>0</effort>
                        <lower>0</lower>
                        <upper>0</upper>
                    </limit>
                </axis>
            </joint>
            <joint name="pitch_joint" type="revolute">
                <pose relative_to="hinge">0 0 0 0 0 0</pose>
                <parent>hinge</parent>
                <child>wing</child>
                <axis>
                    <xyz>1 0 0</xyz>
                    <dynamics>
                        <damping>0.002</damping>
                        <spring_stiffness>.18</spring_stiffness>
                    </dynamics>
                    <limit>
                        <effort>0</effort>
                        <lower>-1.79769e+8</lower>
                        <upper>1.79769e+8</upper>
                    </limit>
                </axis>
            </joint>
            <joint name="stroke_joint" type="revolute">
                <pose relative_to="body">0.0125 0.0125 0 0 0 0</pose>
                <parent>body</parent>
                <child>hinge</child>
                <axis>
                    <xyz>0 1 0</xyz>
                    <dynamics>
                        <damping>.001</damping>
                        <spring_stiffness>5</spring_stiffness>
                    </dynamics>
                    <limit>
                        <lower>-1.79769e+5</lower>
                        <upper>1.79769e+5</upper>
                    </limit>
                </axis>
            </joint>
            <plugin filename="aero_state_plugins" name="aerodynamics">
                <data_file_path>/home/darin/Github/ros2-gazebo-drake-sims/flapping_proj/optimization/data/aero.csv</data_file_path>
                <only_data>false</only_data>
                <link>
                    <link_name>wing</link_name>
                    <link_type>wing</link_type>
                    <stall_angle>15</stall_angle>
                    <fluid_density>1.293</fluid_density>
                    <drag_coefficient>1.28</drag_coefficient>
                    <lift_coefficient>1</lift_coefficient>
                    <control_joint>stroke_joint</control_joint>
                    <wing_pitch_joint>pitch_joint</wing_pitch_joint>
                    <blades>15</blades>
                    <center_pressure_list>0.028636352265433332, -0.004537783524709884, 0, 0.035766567376300004, -0.012171444789744489, 0, 0.04289678248716666, -0.01979892435814629, 0, 0.050026997598033335, -0.02403548713375, 0, 0.05715721270889999, -0.021975298933749995, 0, 0.06428742781976667, -0.019907325310263027, 0, 0.07141764293063334, -0.01784383420332916, 0, 0.0785478580415, -0.01577511349375, 0, 0.08567807315236667, -0.013716851989461426, 0, 0.09280828826323333, -0.011653360882527556, 0, 0.09993850337409999, -0.009574928053749997, 0, 0.10706871848496667, -0.007514739853750001, 0, 0.11419893359583334, -0.005454551653749997, 0, 0.1213291487067, -0.0033747426137499953, 0, 0.12845936381756667, -0.0013145544137499986, 0</center_pressure_list>
                    <upward_vector_list>0,0,1, 0,0,1, 0,0,1, 0,0,1, 0,0,1, 0,0,1, 0,0,1, 0,0,1, 0,0,1, 0,0,1, 0,0,1, 0,0,1, 0,0,1, 0,0,1, 0,0,1</upward_vector_list>
                    <chord_direction_list>0,0,1, 0,0,1, 0,0,1, 0,0,1, 0,0,1, 0,0,1, 0,0,1, 0,0,1, 0,0,1, 0,0,1, 0,0,1, 0,0,1, 0,0,1, 0,0,1, 0,0,1</chord_direction_list>
                    <blade_area_list>0.00012942149063091288, 0.00034714007824366205, 0.0005646823585494432, 0.0006855127742324224, 0.0006267544340929455, 0.0005677740469767036, 0.0005089215050895082, 0.0004499198104350916, 0.00039121642131511745, 0.000332363879427922, 0.0002730851867772376, 0.00021432684663776088, 0.000155568506498284, 9.625056311938356e-05, 3.749222297990685e-05</blade_area_list>
                </link>
            </plugin>
            <plugin filename="aero_state_plugins" name="odometry_state">
                <world_name>world2</world_name>
                <odometry_topic>/odom</odometry_topic>
                <odom_publish_frequency>1000.0</odom_publish_frequency>
                <joint>pitch_joint</joint>
                <joint>stroke_joint</joint>
            </plugin>
            <plugin filename="libignition-gazebo-apply-joint-force-system.so" name="ignition::gazebo::systems::ApplyJointForce">
                <joint_name>stroke_joint</joint_name>
            </plugin>
            <plugin filename="libignition-gazebo-apply-joint-force-system.so" name="ignition::gazebo::systems::ApplyJointForce">
                <joint_name>pitch_joint</joint_name>
            </plugin>
        </model>
    </world>
</sdf>