<?xml version="1.0" ?>
<sdf version="1.8">
    <world name="world2">
        <physics name="1ms" type="ignored">
            <max_step_size>0.0001</max_step_size>
            <real_time_factor> 1</real_time_factor>
        </physics>
        <plugin filename="libignition-gazebo-physics-system.so" name="ignition::gazebo::systems::Physics">
        </plugin>
        <plugin filename="libignition-gazebo-user-commands-system.so" name="ignition::gazebo::systems::UserCommands">
        </plugin>
        <plugin filename="libignition-gazebo-scene-broadcaster-system.so" name="ignition::gazebo::systems::SceneBroadcaster">
        </plugin>
        <light type="directional" name="sun">
            <cast_shadows>true</cast_shadows>
            <pose>0 0 10 0 0 0</pose>
            <diffuse>0.8 0.8 0.8 1</diffuse>
            <specular>0.2 0.2 0.2 1</specular>
            <attenuation>
                <range>1000</range>
                <constant>0.9</constant>
                <linear>0.01</linear>
                <quadratic>0.001</quadratic>
            </attenuation>
            <direction>-0.5 0.1 -0.9</direction>
        </light>
        <model name="ground_plane">
            <pose relative_to="world">0 0 0 0 0 0</pose>
            <static>true</static>
            <link name="link">
                <collision name="link">
                    <geometry>
                        <plane>
                            <normal>0 0 1</normal>
                        </plane>
                    </geometry>
                </collision>
                <visual name="link">
                    <geometry>
                        <plane>
                            <normal>0 0 1</normal>
                            <size>100 100</size>
                        </plane>
                    </geometry>
                    <material>
                        <ambient>0.8 0.8 0.8 1</ambient>
                        <diffuse>0.8 0.8 0.8 1</diffuse>
                        <specular>0.8 0.8 0.8 1</specular>
                    </material>
                </visual>
            </link>
        </model>
        <model name="URDF_LargeWings">
            <pose relative_to="world">0 0 .5 1.5708 0 0</pose>
            <link name="body">
                <pose>0 0 0 0 0 0</pose>
                <inertial>
                    <pose>0 0 0 0 0 0</pose>
                    <mass>1.0</mass>
                    <inertia>
                        <ixx>0.1</ixx>
                        <ixy>0</ixy>
                        <ixz>0</ixz>
                        <iyy>0.1</iyy>
                        <iyz>0</iyz>
                        <izz>0.2</izz>
                    </inertia>
                </inertial>
                <visual name="body">
                    <pose>0 0 0 0 0 0</pose>
                    <geometry>
                        <box>
                            <size>0.025 0.025 0.01</size>
                        </box>
                    </geometry>
                    <material>
                        <ambient>0.0 0.0 1.0 1</ambient>
                        <diffuse>0.0 0.0 1.0 1</diffuse>
                        <specular>0.0 0.0 1.0 1</specular>
                    </material>
                </visual>
            </link>
            <link name="hinge">
                <pose relative_to="stroke_joint">0 0 0 0 0 0</pose>
                <inertial>
                    <mass>0.0057</mass>
                    <inertia>
                        <ixx>20.03e-9</ixx>
                        <ixy>-0.05e-9</ixy>
                        <ixz>4.55e-9</ixz>
                        <iyy>31.49e-9</iyy>
                        <iyz>0.02e-9</iyz>
                        <izz>11.75e-9</izz>
                    </inertia>
                </inertial>
                <visual name="hinge">
                    <pose relative_to="stroke_joint">0 0 0 0 0 0</pose>
                    <geometry>
                        <sphere>
                            <radius>0.0025</radius>
                        </sphere>
                    </geometry>
                    <material>
                        <ambient>1.0 0.0 1.0 .9</ambient>
                        <diffuse>1.0 0.0 1.0 .9</diffuse>
                        <specular>1.0 0.0 1.0 .9</specular>
                    </material>
                </visual>
            </link>
            <link name="wing">
                <pose relative_to="pitch_joint">0 0 0 0 0 0</pose>
                <inertial>
                    <pose>0.04084035952241464, 0, -0.0019658771699151236, 0, 0, 0</pose>
                    <mass>0.00017138360745254133</mass>
                    <inertia>
                        <ixx>5.6057e-08</ixx>
                        <ixy>0.0</ixy>
                        <ixz>2.182e-08</ixz>
                        <iyy>1.307e-07</iyy>
                        <iyz>0.0</iyz>
                        <izz>9.8901e-08</izz>
                    </inertia>
                </inertial>
                <visual name="wing">
                    <pose relative_to="pitch_joint">0 0 0 0 0 0</pose>
                    <geometry>
                        <mesh>
                            <uri>model://URDF_LargeWings/meshes/RW_Pitch.STL</uri>
                        </mesh>
                    </geometry>
                    <material>
                        <ambient>1.0 0.0 0.0 .9</ambient>
                        <diffuse>1.0 0.0 0.0 .9</diffuse>
                        <specular>1.0 0.0 0.0 .9</specular>
                    </material>
                </visual>
                <collision name="wing">
                    <pose relative_to="pitch_joint">0 0 0 0 0 0</pose>
                    <geometry>
                        <mesh>
                            <uri>model://URDF_LargeWings/meshes/RW_Pitch.STL</uri>
                        </mesh>
                    </geometry>
                </collision>
            </link>
            <joint name="anchor2" type="revolute">
                <pose relative_to="body">0 0 0 0 0 0</pose>
                <parent>world</parent>
                <child>body</child>
                <axis>
                    <xyz>0 1 0</xyz>
                    <limit>
                        <effort>0</effort>
                        <lower>0</lower>
                        <upper>0</upper>
                    </limit>
                </axis>
            </joint>
            <joint name="pitch_joint" type="revolute">
                <pose relative_to="hinge">0 0 0 0 0 0</pose>
                <parent>hinge</parent>
                <child>wing</child>
                <axis>
                    <xyz>1 0 0</xyz>
                    <dynamics>
                        <damping>1e-16</damping>
                        <spring_stiffness>1.0871202214559054e-10</spring_stiffness>
                        <spring_reference>-1.57</spring_reference>
                    </dynamics>
                    <limit>
                        <effort>0</effort>
                        <lower>-1.571</lower>
                        <upper>1.571</upper>
                    </limit>
                </axis>
            </joint>
            <joint name="stroke_joint" type="revolute">
                <pose relative_to="body">0.0125 0.0125 0 0 0 0</pose>
                <parent>body</parent>
                <child>hinge</child>
                <axis>
                    <xyz>0 1 0</xyz>
                    <dynamics>
                        <damping>1e-15</damping>
                        <spring_stiffness>0.01500836656384201</spring_stiffness>
                    </dynamics>
                    <limit>
                        <lower>-1.571</lower>
                        <upper>1.571</upper>
                    </limit>
                </axis>
            </joint>
            <plugin filename="aero_state_plugins" name="aerodynamics">
                <data_file_path>/home/darin/Github/ros2-gazebo-drake-sims/flapping_proj/optimization/data/aero.csv</data_file_path>
                <only_data>false</only_data>
                <link>
                    <link_name>wing</link_name>
                    <link_type>wing</link_type>
                    <stall_angle>15</stall_angle>
                    <fluid_density>1.293</fluid_density>
                    <drag_coefficient>1.28</drag_coefficient>
                    <lift_coefficient>1</lift_coefficient>
                    <control_joint>stroke_joint</control_joint>
                    <wing_pitch_joint>pitch_joint</wing_pitch_joint>
                    <blades>15</blades>
                    <center_pressure_list>0.029590657425, -0.009574062951554422, 0, 0.033303990281, -0.010579194783921343, 0, 0.037017323137, -0.009809931760289216, 0, 0.040730655993, -0.009039568547331232, 0, 0.044443988849, -0.008273268936883266, 0, 0.048157321705, -0.007507696870989495, 0, 0.051870654561, -0.006737333658031512, 0, 0.055583987417000005, -0.005975825194647757, 0, 0.059297320273, -0.005205461981689775, 0, 0.063010653129, -0.004435098768731792, 0, 0.066723985985, -0.003661417242807115, 0, 0.070437318841, -0.0028847126160075724, 0, 0.07415065169700001, -0.0021093517688391804, 0, 0.077863984553, -0.0013554913957690394, 0, 0.081577317409, -0.0006016310226989001, 0</center_pressure_list>
                    <upward_vector_list>0,0,1, 0,0,1, 0,0,1, 0,0,1, 0,0,1, 0,0,1, 0,0,1, 0,0,1, 0,0,1, 0,0,1, 0,0,1, 0,0,1, 0,0,1, 0,0,1, 0,0,1</upward_vector_list>
                    <chord_direction_list>0,0,1, 0,0,1, 0,0,1, 0,0,1, 0,0,1, 0,0,1, 0,0,1, 0,0,1, 0,0,1, 0,0,1, 0,0,1, 0,0,1, 0,0,1, 0,0,1, 0,0,1</chord_direction_list>
                    <blade_area_list>0.0001422067300936775, 0.0001571362863246358, 0.00014571016768239945, 0.00013426770756347703, 0.00012288560547941128, 0.00011151430985573476, 0.00010007184973681234, 8.876091214799244e-05, 7.731845202907005e-05, 6.587599191014763e-05, 5.438424378896236e-05, 4.2847592548554526e-05, 3.1330900912368985e-05, 2.0133562943737895e-05, 8.936224975106831e-06</blade_area_list>
                </link>
            </plugin>
            <plugin filename="aero_state_plugins" name="odometry_state">
                <world_name>world2</world_name>
                <odometry_topic>/odom</odometry_topic>
                <odom_publish_frequency>1000.0</odom_publish_frequency>
                <joint>pitch_joint</joint>
                <joint>stroke_joint</joint>
            </plugin>
            <plugin filename="libignition-gazebo-apply-joint-force-system.so" name="ignition::gazebo::systems::ApplyJointForce">
                <joint_name>stroke_joint</joint_name>
            </plugin>
            <plugin filename="libignition-gazebo-apply-joint-force-system.so" name="ignition::gazebo::systems::ApplyJointForce">
                <joint_name>pitch_joint</joint_name>
            </plugin>
        </model>
    </world>
</sdf>