<?xml version="1.0" ?>
<sdf version="1.8">
    <world name="world2">
        <physics name="1ms" type="ignored">
            <max_step_size>0.0001</max_step_size>
            <real_time_factor> 1</real_time_factor>
        </physics>
        <plugin filename="libignition-gazebo-physics-system.so" name="ignition::gazebo::systems::Physics">
        </plugin>
        <plugin filename="libignition-gazebo-user-commands-system.so" name="ignition::gazebo::systems::UserCommands">
        </plugin>
        <plugin filename="libignition-gazebo-scene-broadcaster-system.so" name="ignition::gazebo::systems::SceneBroadcaster">
        </plugin>
        <light type="directional" name="sun">
            <cast_shadows>true</cast_shadows>
            <pose>0 0 10 0 0 0</pose>
            <diffuse>0.8 0.8 0.8 1</diffuse>
            <specular>0.2 0.2 0.2 1</specular>
            <attenuation>
                <range>1000</range>
                <constant>0.9</constant>
                <linear>0.01</linear>
                <quadratic>0.001</quadratic>
            </attenuation>
            <direction>-0.5 0.1 -0.9</direction>
        </light>
        <model name="ground_plane">
            <pose relative_to="world">0 0 0 0 0 0</pose>
            <static>true</static>
            <link name="link">
                <collision name="link">
                    <geometry>
                        <plane>
                            <normal>0 0 1</normal>
                        </plane>
                    </geometry>
                </collision>
                <visual name="link">
                    <geometry>
                        <plane>
                            <normal>0 0 1</normal>
                            <size>100 100</size>
                        </plane>
                    </geometry>
                    <material>
                        <ambient>0.8 0.8 0.8 1</ambient>
                        <diffuse>0.8 0.8 0.8 1</diffuse>
                        <specular>0.8 0.8 0.8 1</specular>
                    </material>
                </visual>
            </link>
        </model>
        <model name="URDF_LargeWings">
            <pose relative_to="world">0 0 .5 1.5708 0 0</pose>
            <link name="body">
                <pose>0 0 0 0 0 0</pose>
                <inertial>
                    <pose>0 0 0 0 0 0</pose>
                    <mass>1.0</mass>
                    <inertia>
                        <ixx>0.1</ixx>
                        <ixy>0</ixy>
                        <ixz>0</ixz>
                        <iyy>0.1</iyy>
                        <iyz>0</iyz>
                        <izz>0.2</izz>
                    </inertia>
                </inertial>
                <visual name="body">
                    <pose>0 0 0 0 0 0</pose>
                    <geometry>
                        <box>
                            <size>0.025 0.025 0.01</size>
                        </box>
                    </geometry>
                    <material>
                        <ambient>0.0 0.0 1.0 1</ambient>
                        <diffuse>0.0 0.0 1.0 1</diffuse>
                        <specular>0.0 0.0 1.0 1</specular>
                    </material>
                </visual>
            </link>
            <link name="hinge">
                <pose relative_to="stroke_joint">0 0 0 0 0 0</pose>
                <inertial>
                    <mass>0.0057</mass>
                    <inertia>
                        <ixx>20.03e-9</ixx>
                        <ixy>-0.05e-9</ixy>
                        <ixz>4.55e-9</ixz>
                        <iyy>31.49e-9</iyy>
                        <iyz>0.02e-9</iyz>
                        <izz>11.75e-9</izz>
                    </inertia>
                </inertial>
                <visual name="hinge">
                    <pose relative_to="stroke_joint">0 0 0 0 0 0</pose>
                    <geometry>
                        <sphere>
                            <radius>0.0025</radius>
                        </sphere>
                    </geometry>
                    <material>
                        <ambient>1.0 0.0 1.0 .9</ambient>
                        <diffuse>1.0 0.0 1.0 .9</diffuse>
                        <specular>1.0 0.0 1.0 .9</specular>
                    </material>
                </visual>
            </link>
            <link name="wing">
                <pose relative_to="pitch_joint">0 0 0 0 0 0</pose>
                <inertial>
                    <pose>0.08219744069148373, 0, -0.0019530338795320206, 0, 0, 0</pose>
                    <mass>0.0005521166764927275</mass>
                    <inertia>
                        <ixx>6.992611579e-06</ixx>
                        <ixy>0.0</ixy>
                        <ixz>2.455676501e-06</ixz>
                        <iyy>7.586915596e-06</iyy>
                        <iyz>0.0</iyz>
                        <izz>3.043229845e-06</izz>
                    </inertia>
                </inertial>
                <visual name="wing">
                    <pose relative_to="pitch_joint">0 0 0 0 0 0</pose>
                    <geometry>
                        <mesh>
                            <uri>model://URDF_LargeWings/meshes/RW_Pitch.STL</uri>
                        </mesh>
                    </geometry>
                    <material>
                        <ambient>1.0 0.0 0.0 .9</ambient>
                        <diffuse>1.0 0.0 0.0 .9</diffuse>
                        <specular>1.0 0.0 0.0 .9</specular>
                    </material>
                </visual>
                <collision name="wing">
                    <pose relative_to="pitch_joint">0 0 0 0 0 0</pose>
                    <geometry>
                        <mesh>
                            <uri>model://URDF_LargeWings/meshes/RW_Pitch.STL</uri>
                        </mesh>
                    </geometry>
                </collision>
            </link>
            <joint name="anchor2" type="revolute">
                <pose relative_to="body">0 0 0 0 0 0</pose>
                <parent>world</parent>
                <child>body</child>
                <axis>
                    <xyz>0 1 0</xyz>
                    <limit>
                        <effort>0</effort>
                        <lower>0</lower>
                        <upper>0</upper>
                    </limit>
                </axis>
            </joint>
            <joint name="pitch_joint" type="revolute">
                <pose relative_to="hinge">0 0 0 0 0 0</pose>
                <parent>hinge</parent>
                <child>wing</child>
                <axis>
                    <xyz>1 0 0</xyz>
                    <dynamics>
                        <damping>0.002</damping>
                        <spring_stiffness>.18</spring_stiffness>
                    </dynamics>
                    <limit>
                        <effort>0</effort>
                        <lower>-1.79769e+8</lower>
                        <upper>1.79769e+8</upper>
                    </limit>
                </axis>
            </joint>
            <joint name="stroke_joint" type="revolute">
                <pose relative_to="body">0.0125 0.0125 0 0 0 0</pose>
                <parent>body</parent>
                <child>hinge</child>
                <axis>
                    <xyz>0 1 0</xyz>
                    <dynamics>
                        <damping>.001</damping>
                        <spring_stiffness>5</spring_stiffness>
                    </dynamics>
                    <limit>
                        <lower>-1.79769e+5</lower>
                        <upper>1.79769e+5</upper>
                    </limit>
                </axis>
            </joint>
            <plugin filename="aero_state_plugins" name="aerodynamics">
                <data_file_path>/home/darin/Github/ros2-gazebo-drake-sims/flapping_proj/optimization/data/aero.csv</data_file_path>
                <only_data>false</only_data>
                <link>
                    <link_name>wing</link_name>
                    <link_type>wing</link_type>
                    <stall_angle>15</stall_angle>
                    <fluid_density>1.293</fluid_density>
                    <drag_coefficient>1.28</drag_coefficient>
                    <lift_coefficient>1</lift_coefficient>
                    <control_joint>stroke_joint</control_joint>
                    <wing_pitch_joint>pitch_joint</wing_pitch_joint>
                    <blades>15</blades>
                    <center_pressure_list>0.030409848384533332, -0.003092522278736295, 0, 0.0382891140636, -0.008154315254966786, 0, 0.04616837974266667, -0.013216108231197279, 0, 0.054047645421733334, -0.018317139912669866, 0, 0.061926911100799995, -0.02337893288890036, 0, 0.06980617677986667, -0.028446151658040073, 0, 0.07768544245893334, -0.03355536134621643, 0, 0.085564708138, -0.038642789228076034, 0, 0.09344397381706666, -0.04370458220430653, 0, 0.10132323949613332, -0.04868648234581563, 0, 0.1092025051752, -0.041958019429499005, 0, 0.11708177085426667, -0.03266453338275753, 0, 0.12496103653333333, -0.023371047336016033, 0, 0.1328403022124, -0.014189410680767664, 0, 0.1407195678914667, -0.004981808988208422, 0</center_pressure_list>
                    <upward_vector_list>0,0,1, 0,0,1, 0,0,1, 0,0,1, 0,0,1, 0,0,1, 0,0,1, 0,0,1, 0,0,1, 0,0,1, 0,0,1, 0,0,1, 0,0,1, 0,0,1, 0,0,1</upward_vector_list>
                    <chord_direction_list>0,0,1, 0,0,1, 0,0,1, 0,0,1, 0,0,1, 0,0,1, 0,0,1, 0,0,1, 0,0,1, 0,0,1, 0,0,1, 0,0,1, 0,0,1, 0,0,1, 0,0,1</chord_direction_list>
                    <blade_area_list>9.746721861038372e-05, 0.0002570000652989982, 0.0004165329119876128, 0.0005773024474102475, 0.0007368352940988622, 0.0008965391458428821, 0.0010575664280156937, 0.0012179072116327465, 0.0013774400583213612, 0.0015344549175274813, 0.0013223935298098555, 0.0010294901472219554, 0.0007365867646340544, 0.0004472085463326186, 0.00015701198632182584</blade_area_list>
                </link>
            </plugin>
            <plugin filename="aero_state_plugins" name="odometry_state">
                <world_name>world2</world_name>
                <odometry_topic>/odom</odometry_topic>
                <odom_publish_frequency>1000.0</odom_publish_frequency>
                <joint>pitch_joint</joint>
                <joint>stroke_joint</joint>
            </plugin>
            <plugin filename="libignition-gazebo-apply-joint-force-system.so" name="ignition::gazebo::systems::ApplyJointForce">
                <joint_name>stroke_joint</joint_name>
            </plugin>
            <plugin filename="libignition-gazebo-apply-joint-force-system.so" name="ignition::gazebo::systems::ApplyJointForce">
                <joint_name>pitch_joint</joint_name>
            </plugin>
        </model>
    </world>
</sdf>