<?xml version="1.0" ?>
<sdf version="1.8">
   <world name="world1">
      <physics name="1ms" type="ignored">
         <max_step_size>0.001</max_step_size>
         <real_time_factor>1.0</real_time_factor>
      </physics>
      <plugin filename="libignition-gazebo-physics-system.so" name="ignition::gazebo::systems::Physics">
        </plugin>
      <plugin filename="libignition-gazebo-user-commands-system.so" name="ignition::gazebo::systems::UserCommands">
        </plugin>
      <plugin filename="libignition-gazebo-scene-broadcaster-system.so" name="ignition::gazebo::systems::SceneBroadcaster">
        </plugin>
      <!-- <plugin
      filename="ignition-gazebo-apply-link-wrench-system"
      name="ignition::gazebo::systems::ApplyLinkWrench">
      <topic>/gazebo/apply_body_wrench</topic>
      <persistent>
        <entity_name>URDF_Bodies2.SLDASM</entity_name>
        <entity_type>model</entity_type>
        <force>0 0 100</force>
        <torque>0 0 0</torque>
      </persistent>
    </plugin> -->
      <light type="directional" name="sun">
         <cast_shadows>true</cast_shadows>
         <pose>0 0 10 0 0 0</pose>
         <diffuse>0.8 0.8 0.8 1</diffuse>
         <specular>0.2 0.2 0.2 1</specular>
         <attenuation>
            <range>1000</range>
            <constant>0.9</constant>
            <linear>0.01</linear>
            <quadratic>0.001</quadratic>
         </attenuation>
         <direction>-0.5 0.1 -0.9</direction>
      </light>
      <model name="ground_plane">
         <pose relative_to="world">0 0 0 0 0 0</pose>
         <static>true</static>
         <link name="link">
            <collision name="link">
               <geometry>
                  <plane>
                     <normal>0 0 1</normal>
                  </plane>
               </geometry>
            </collision>
            <visual name="link">
               <geometry>
                  <plane>
                     <normal>0 0 1</normal>
                     <size>100 100</size>
                  </plane>
               </geometry>
               <material>
                  <ambient>0.8 0.8 0.8 1</ambient>
                  <diffuse>0.8 0.8 0.8 1</diffuse>
                  <specular>0.8 0.8 0.8 1</specular>
               </material>
            </visual>
         </link>
      </model>
      <model name="URDF_Bodies2SLDASM"> <!-- removed . because its used as topic name for joint force plugin-->
         <pose relative_to="world">0 0 10 0 0 0< /pose>
         <link name="base_link">
            <pose>0 0 0 0 0 0</pose>
            <inertial>
               <pose>1.287E-17 -0.125 1.1123E-17 0 0 0</pose>
               <mass>3.7513</mass>
               <!-- <mass>10e20</mass> -->
               <inertia>
                  <ixx>0.020361</ixx>
                  <ixy>0</ixy>
                  <ixz>0</ixz>
                  <iyy>0.027094</iyy>
                  <iyz>1.1459E-18</iyz>
                  <izz>0.045808</izz>
               </inertia>
            </inertial>
            <visual name="base_link">
               <pose>0 0 0 0 0 0</pose>
               <geometry>
                  <mesh>
                     <uri>model://URDF_Bodies2.SLDASM/meshes/base_link.STL</uri>
                  </mesh>
               </geometry>
               <material>
                  <ambient>0.0 0.0 1.0 1</ambient>
                  <diffuse>0.0 0.0 1.0 1</diffuse>
                  <specular>0.0 0.0 1.0 1</specular>

               </material>
            </visual>
            <collision name="base_link">
               <pose>0 0 0 0 0 0</pose>
               <geometry>
                  <mesh>
                     <uri>model://URDF_Bodies2.SLDASM/meshes/base_link.STL</uri>
                  </mesh>
               </geometry>
            </collision>
             
         </link>
         <!-- <plugin filename="libignition-gazebo6-velocity-control-system.so" name="ignition::gazebo::systems::VelocityControl"> -->
               <!-- <topic>/cmd_vel</topic> -->
               <!-- <link_name>base_link</link_name> -->
               <!-- <initial_velocity>0 0 -10</initial_velocity> -->
               <!-- <initial_angular>5 0 0</initial_angular> -->
         <!-- </plugin> -->
         <!-- <plugin
            filename="velocity_control"
            name="ignition::gazebo::VelocityControl">
            <initial_angular>50 0 0</initial_angular>
         </plugin> -->

         <link name="RW_Flap">
            <pose relative_to="joint_RW_J_Flap">0 0 0 0 0 0</pose>
            <inertial>
               <pose>0.032766 0.034001 -8.7011E-19 0 0 0</pose>
               <mass>0.15563</mass>
               <inertia>
                  <ixx>4.7427E-05</ixx>
                  <ixy>-3.1144E-05</ixy>
                  <ixz>-3.1293E-21</ixz>
                  <iyy>0.00016366</iyy>
                  <iyz>-6.839E-22</iyz>
                  <izz>0.00017996</izz>
               </inertia>
            </inertial>
            <visual name="RW_Flap">
               <pose relative_to="joint_RW_J_Flap">0 0 0 0 0 0</pose>
               <geometry>
                  <mesh>
                     <uri>model://URDF_Bodies2.SLDASM/meshes/RW_Flap.STL</uri>
                  </mesh>
               </geometry>
            </visual>
            <collision name="RW_Flap">
               <pose relative_to="joint_RW_J_Flap">0 0 0 0 0 0</pose>
               <geometry>
                  <mesh>
                     <uri>model://URDF_Bodies2.SLDASM/meshes/RW_Flap.STL</uri>
                  </mesh>
               </geometry>
            </collision>
         </link>
         <joint name="joint_RW_J_Flap" type="revolute">
            <pose relative_to="base_link">0.12329 0 0 0 0 0</pose>
            <parent>base_link</parent>
            <child>RW_Flap</child>
            <axis>
               <xyz>0 -1 0</xyz>
               <limit>
                  <lower>-1.79769e+308</lower>
                  <upper>1.79769e+308</upper>
               </limit>
            </axis>
         </joint>
         <link name="RW_Pitch">
            <pose relative_to="joint_RW_J_Pitch">0 0 0 0 0 0</pose>
            <inertial>
               <pose>0.375 -0.050083 7.3865E-18 0 0 0</pose>
               <mass>2.3629</mass>
               <inertia>
                  <ixx>0.014446</ixx>
                  <ixy>6.0467E-18</ixy>
                  <ixz>4.4759E-19</ixz>
                  <iyy>0.111</iyy>
                  <iyz>7.9212E-19</iyz>
                  <izz>0.12497</izz>
               </inertia>
            </inertial>
            <visual name="RW_Pitch">
               <pose relative_to="joint_RW_J_Pitch">0 0 0 0 0 0</pose>
               <geometry>
                  <mesh>
                     <uri>model://URDF_Bodies2.SLDASM/meshes/RW_Pitch.STL</uri>
                  </mesh>
               </geometry>
            </visual>
            <collision name="RW_Pitch">
               <pose relative_to="joint_RW_J_Pitch">0 0 0 0 0 0</pose>
               <geometry>
                  <mesh>
                     <uri>model://URDF_Bodies2.SLDASM/meshes/RW_Pitch.STL</uri>
                  </mesh>
               </geometry>
            </collision>
         </link>
         <joint name="joint_RW_J_Pitch" type="revolute">
            <pose relative_to="RW_Flap">0.09 0.04 0 0 0 0</pose>
            <parent>RW_Flap</parent>
            <child>RW_Pitch</child>
            <axis>
               <xyz>-1 0 0</xyz>
               <limit>
                  <lower>-1.79769e+308</lower>
                  <upper>1.79769e+308</upper>
               </limit>
            </axis>
         </joint>
         <link name="LW_Flap">
            <pose relative_to="joint_LW_J_Flap">0 0 0 0 0 0</pose>
            <inertial>
               <pose>0.032766 0.034001 -8.7011E-19 0 0 0</pose>
               <mass>0.15563</mass>
               <inertia>
                  <ixx>4.7427E-05</ixx>
                  <ixy>-3.1144E-05</ixy>
                  <ixz>-3.1293E-21</ixz>
                  <iyy>0.00016366</iyy>
                  <iyz>-6.839E-22</iyz>
                  <izz>0.00017996</izz>
               </inertia>
            </inertial>
            <visual name="LW_Flap">
               <pose relative_to="joint_LW_J_Flap">0 0 0 0 0 0</pose>
               <geometry>
                  <mesh>
                     <uri>model://URDF_Bodies2.SLDASM/meshes/LW_Flap.STL</uri>
                  </mesh>
               </geometry>
            </visual>
            <collision name="LW_Flap">
               <pose relative_to="joint_LW_J_Flap">0 0 0 0 0 0</pose>
               <geometry>
                  <mesh>
                     <uri>model://URDF_Bodies2.SLDASM/meshes/LW_Flap.STL</uri>
                  </mesh>
               </geometry>
            </collision>
         </link>
         <joint name="joint_LW_J_Flap" type="revolute">
            <pose relative_to="base_link">-0.12329 0 0 0 0 0</pose>
            <parent>base_link</parent>
            <child>LW_Flap</child>
            <axis>
               <xyz>0 -1 0</xyz>
               <limit>
                  <lower>-1.79769e+308</lower>
                  <upper>1.79769e+308</upper>
               </limit>
            </axis>
         </joint>
         <link name="LW_Pitch">
            <pose relative_to="joint_LW_J_Pitch">0 0 0 0 0 0</pose>
            <inertial>
               <pose>-0.375 -0.050083 1.3712E-18 0 0 0</pose>
               <mass>2.3629</mass>
               <!-- <mass>100</mass> -->
               <inertia>
                  <ixx>0.014446</ixx>
                  <ixy>6.0467E-18</ixy>
                  <ixz>4.4759E-19</ixz>
                  <iyy>0.111</iyy>
                  <iyz>-8.8618E-19</iyz>
                  <izz>0.12497</izz>
               </inertia>
            </inertial>
            <visual name="LW_Pitch">
               <pose relative_to="joint_LW_J_Pitch">0 0 0 0 0 0</pose>
               <geometry>
                  <mesh>
                     <uri>model://URDF_Bodies2.SLDASM/meshes/LW_Pitch.STL</uri>
                  </mesh>
               </geometry>
            </visual>
            <collision name="LW_Pitch">
               <pose relative_to="joint_LW_J_Pitch">0 0 0 0 0 0</pose>
               <geometry>
                  <mesh>
                     <uri>model://URDF_Bodies2.SLDASM/meshes/LW_Pitch.STL</uri>
                  </mesh>
               </geometry>
            </collision>
         </link>
         <joint name="joint_LW_J_Pitch" type="revolute">
            <pose relative_to="LW_Flap">-0.09 0.04 0 0 0 0</pose>
            <parent>LW_Flap</parent>
            <child>LW_Pitch</child>
            <axis>
               <xyz>1 0 0</xyz>
               <dynamics>
                  <damping>0</damping>
                  <friction>0</friction>   

                  <spring_reference>1.5708</spring_reference>
                  <spring_stiffness>1</spring_stiffness>
               </dynamics>
               <limit>
                  <lower>-1.79769e+308</lower>
                  <upper>1.79769e+308</upper>
               </limit> 
            </axis>
         </joint>
         <plugin 
            filename="odometry_state_plugin" 
            name="odometry_state">
            <world_name>world1</world_name>
            <odometry_topic>/odom</odometry_topic>
            <odom_publish_frequency>20.0</odom_publish_frequency>
            <joint>joint_LW_J_Flap</joint> 
            <joint>joint_LW_J_Pitch</joint>
            <joint>joint_RW_J_Pitch</joint>
            <joint>joint_RW_J_Flap</joint>
         </plugin>
         
         

         <!-- subscribes to model_name/joint/jointname/cmd_force , takes doubles -->
         <plugin  
            filename="libignition-gazebo-apply-joint-force-system.so" 
            name = "ignition::gazebo::systems::ApplyJointForce">
            <joint_name>joint_LW_J_Pitch</joint_name>
         </plugin>
         <plugin  
            filename="libignition-gazebo-apply-joint-force-system.so" 
            name = "ignition::gazebo::systems::ApplyJointForce">
            <joint_name>joint_LW_J_Flap</joint_name>
         </plugin>
         <plugin  
            filename="libignition-gazebo-apply-joint-force-system.so" 
            name = "ignition::gazebo::systems::ApplyJointForce">
            <joint_name>joint_RW_J_Pitch</joint_name>
         </plugin>
         <plugin  
            filename="libignition-gazebo-apply-joint-force-system.so" 
            name = "ignition::gazebo::systems::ApplyJointForce">
         <joint_name>joint_RW_J_Flap</joint_name> 
         </plugin>
         <!--
         <plugin filename="libignition-gazebo-joint-controller-system.so" name="ignition::gazebo::systems::JointController">
            <joint_name>joint_LW_J_Pitch</joint_name>
            <use_force_commands>true</use_force_commands>
            <topic>cmd_vel</topic>
            <initial_velocity>100</initial_velocity>
         </plugin>

         <plugin filename="libignition-gazebo-joint-controller-system.so" name="ignition::gazebo::systems::JointController">
            <joint_name>joint_LW_J_Flap</joint_name>
            <use_force_commands>false</use_force_commands>
            <topic>cmd_vel</topic>
            <initial_velocity>10</initial_velocity>
         </plugin>

         <plugin filename="libignition-gazebo-joint-controller-system.so" name="ignition::gazebo::systems::JointController">
            <joint_name>joint_RW_J_Pitch</joint_name>
            <use_force_commands>true</use_force_commands>
            <topic>cmd_vel</topic>
            <initial_velocity>5</initial_velocity>
         </plugin>

         <plugin filename="libignition-gazebo-joint-controller-system.so" name="ignition::gazebo::systems::JointController">
            <joint_name>joint_RW_J_Flap</joint_name>
            <use_force_commands>true</use_force_commands>
            <topic>cmd_vel</topic>
            <initial_velocity>10</initial_velocity>
         </plugin> -->

         <plugin filename="libignition-gazebo-triggered-publisher-system.so"
                name="ignition::gazebo::systems::TriggeredPublisher">
            <input type="ignition.msgs.Int32" topic="/keyboard/keypress">
                <match field="data">16777237</match>
            </input>
            <output type="ignition.msgs.Double" topic="/cmd_vel">
            <!-- <output type="ignition.msgs.Twist" topic="/motor_speeds"> -->
               data: 3
            </output>
        </plugin>

        <plugin filename="libignition-gazebo-triggered-publisher-system.so"
                name="ignition::gazebo::systems::TriggeredPublisher">
            <input type="ignition.msgs.Int32" topic="/keyboard/keypress">
                <match field="data">16777235</match>
            </input>
            <output type="ignition.msgs.Double" topic="/cmd_vel">
            <!-- <output type="ignition.msgs.Twist" topic="/motor_speeds"> -->
               data: 3
            </output>
        </plugin>

        <!-- Moving right-->
        <plugin filename="libignition-gazebo-triggered-publisher-system.so"
                name="ignition::gazebo::systems::TriggeredPublisher">
            <input type="ignition.msgs.Int32" topic="/keyboard/keypress">
                <match field="data">16777236</match>
            </input>
            <output type="ignition.msgs.Double" topic="/cmd_vel">
            <!-- <output type="ignition.msgs.Twist" topic="/motor_speeds"> -->
               data: 3
            </output>
        </plugin>

        <!-- Moving left-->
        <plugin filename="libignition-gazebo-triggered-publisher-system.so"
                name="ignition::gazebo::systems::TriggeredPublisher">
            <input type="ignition.msgs.Int32" topic="/keyboard/keypress">
                <match field="data">16777234</match>
            </input>
            <output type="ignition.msgs.Double" topic="/cmd_vel">
            <!-- <output type="ignition.msgs.Twist" topic="/motor_speeds"> -->
               data: 3
            </output>
        </plugin>
      </model>
      <gravity>0 0 0</gravity>
   </world>
</sdf>