<?xml version="1.0" ?>
<sdf version="1.8">
   <world name="world2">
      <physics name="1ms" type="ignored">
         <max_step_size>0.0001</max_step_size>
         <real_time_factor>1.0</real_time_factor>
      </physics>
      <plugin filename="libignition-gazebo-physics-system.so" name="ignition::gazebo::systems::Physics">
        </plugin>
      <plugin filename="libignition-gazebo-user-commands-system.so" name="ignition::gazebo::systems::UserCommands">
        </plugin>
      <plugin filename="libignition-gazebo-scene-broadcaster-system.so" name="ignition::gazebo::systems::SceneBroadcaster">
        </plugin>
      <light type="directional" name="sun">
         <cast_shadows>true</cast_shadows>
         <pose>0 0 10 0 0 0</pose>
         <diffuse>0.8 0.8 0.8 1</diffuse>
         <specular>0.2 0.2 0.2 1</specular>
         <attenuation>
            <range>1000</range>
            <constant>0.9</constant>
            <linear>0.01</linear>
            <quadratic>0.001</quadratic>
         </attenuation>
         <direction>-0.5 0.1 -0.9</direction>
      </light>
      <model name="ground_plane">
         <pose relative_to="world">0 0 0 0 0 0</pose>
         <static>true</static>
         <link name="link">
            <collision name="link">
               <geometry>
                  <plane>
                     <normal>0 0 1</normal>
                  </plane>
               </geometry>
            </collision>
            <visual name="link">
               <geometry>
                  <plane>
                     <normal>0 0 1</normal>
                     <size>3 3</size>
                  </plane>
               </geometry>
               <material>
                  <ambient>0.8 0.8 0.8 1</ambient>
                  <diffuse>0.8 0.8 0.8 1</diffuse>
                  <specular>0.8 0.8 0.8 1</specular>
               </material>
            </visual>
         </link>
      </model>
      <model name="URDF_Tiny"> 
         <pose relative_to="world">0 0 1 1.5708 0 0</pose>
         <link name="base_link">
            <pose>0 0 0 0 0 0</pose>
            <inertial>
               <pose>2.90929190927912E-18 -0.0225 1.75308850064785E-18 0 0 0</pose>
               <mass>0.00635649989496079</mass>
               <inertia>
                  <ixx>1.07828542773576E-06</ixx>
                  <ixy>6.91754242672403E-24</ixy>
                  <ixz>-2.8657332950023E-25</ixz>
                  <iyy>1.53486567387336E-07</iyy>
                  <iyz>6.48370505339519E-23</iyz>
                  <izz>1.22051985420084E-06</izz>
               </inertia>
            </inertial>
            <visual name="base_link">
               <pose>0 0 0 0 0 0</pose>
               <geometry>
                  <mesh>
                     <uri>model://URDF_Tiny/meshes/base_link.STL</uri>
                  </mesh>
               </geometry>
               <material>
                  <ambient>0.0 0.0 1.0 1</ambient>
                  <diffuse>0.0 0.0 1.0 1</diffuse>
                  <specular>0.0 0.0 1.0 1</specular>
               </material>
            </visual>
            <collision name="base_link">
               <pose>0 0 0 0 0 0</pose>
               <geometry>
                  <mesh>
                     <uri>model://URDF_Tiny/meshes/base_link.STL</uri>
                  </mesh>
               </geometry>
            </collision>
         </link>
         <link name="RW_Flap">
            <pose relative_to="joint_RW_J_Flap">0 0 0 0 0 0</pose>
            <inertial>
               <pose>0.00333837466497408 0.00333837466497408 2.6213145100327E-20 0 0 0</pose>
               <mass>3.89068170490654E-05</mass>
               <inertia>
                  <ixx>6.78208726623603E-11</ixx>
                  <ixy>-8.49217730939301E-11</ixy>
                  <ixz>-1.64845713489435E-27</ixz>
                  <iyy>3.57554255139679E-10</iyy>
                  <iyz>1.22977512422724E-27</iyz>
                  <izz>4.05921719277506E-10</izz>
               </inertia>
            </inertial>
            <visual name="RW_Flap">
               <pose relative_to="joint_RW_J_Flap">0 0 0 0 0 0</pose>
               <geometry>
                  <mesh>
                     <uri>model://URDF_Tiny/meshes/RW_Flap.STL</uri>
                  </mesh>
               </geometry>
               <material>
                  <ambient>1.0 0.0 1.0 .9</ambient>
                  <diffuse>1.0 0.0 1.0 .9</diffuse>
                  <specular>1.0 0.0 1.0 .9</specular>
               </material>
            </visual>
            <collision name="RW_Flap">
               <pose relative_to="joint_RW_J_Flap">0 0 0 0 0 0</pose>
               <geometry>
                  <mesh>
                     <uri>model://URDF_Tiny/meshes/RW_Flap.STL</uri>
                  </mesh>
               </geometry>
            </collision>
         </link>
         <link name="RW_Pitch">
            <pose relative_to="joint_RW_J_Pitch">0 0 0 0 0 0</pose>
            <inertial>
               <pose>0.0375 -0.00563011555355997 3.10971969344189E-20 0 0 0</pose>
               <mass>0.000423935026696007</mass>
               <inertia>
                  <ixx>2.65235443608576E-08</ixx>
                  <ixy>-2.93064684625566E-23</ixy>
                  <ixz>-1.65258864845697E-24</ixz>
                  <iyy>1.98779779728036E-07</iyy>
                  <iyz>-3.47087198051225E-26</iyz>
                  <izz>2.25182852160328E-07</izz>
               </inertia>
            </inertial>
            <visual name="RW_Pitch">
               <pose relative_to="joint_RW_J_Pitch">0 0 0 0 0 0</pose>
               <geometry>
                  <mesh>
                     <uri>model://URDF_Tiny/meshes/RW_Pitch.STL</uri>
                  </mesh>
               </geometry>
            </visual>
            <collision name="RW_Pitch">
               <pose relative_to="joint_RW_J_Pitch">0 0 0 0 0 0</pose>
               <geometry>
                  <mesh>
                     <uri>model://URDF_Tiny/meshes/RW_Pitch.STL</uri>
                  </mesh>
               </geometry>
               <material>
                  <ambient>0.0 1.0 0.0 .8</ambient>
                  <diffuse>0.0 1.0 0.0 .8</diffuse>
                  <specular>0.0 1.0 0.0 .75</specular>
               </material>
            </collision>
         </link>
         <link name="LW_Flap">
            <pose relative_to="joint_LW_J_Flap">0 0 0 0 0 0</pose>
            <inertial>
               <pose>-0.00333837466497408 0.00333837466497408 -2.6213145100327E-20 0 0 0</pose>
               <mass>3.89068170490654E-05</mass>
               <inertia>
                  <ixx>6.78208726623603E-11</ixx>
                  <ixy>8.49217730939301E-11</ixy>
                  <ixz>-1.64845713489435E-27</ixz>
                  <iyy>3.57554255139679E-10</iyy>
                  <iyz>-1.22977512422724E-27</iyz>
                  <izz>4.05921719277506E-10</izz>
               </inertia>
            </inertial>
            <visual name="LW_Flap">
               <pose relative_to="joint_LW_J_Flap">0 0 0 0 0 0</pose>
               <geometry>
                  <mesh>
                     <uri>model://URDF_Tiny/meshes/LW_Flap.STL</uri>
                  </mesh>
               </geometry>
               <material>
                  <ambient>0.0 1.0 0.0 .8</ambient>
                  <diffuse>0.0 1.0 0.0 .8</diffuse>
                  <specular>0.0 1.0 0.0 .75</specular>
               </material>
            </visual>
            <collision name="LW_Flap">
               <pose relative_to="joint_LW_J_Flap">0 0 0 0 0 0</pose>
               <geometry>
                  <mesh>
                     <uri>model://URDF_Tiny/meshes/LW_Flap.STL</uri>
                  </mesh>
               </geometry>
            </collision>
         </link>
         <link name="LW_Pitch">
            <pose relative_to="joint_LW_J_Pitch">0 0 0 0 0 0</pose>
            <inertial>
               <pose>-0.0375 -0.00563011555355997 6.26802875709381E-20 0 0 0</pose>
               <mass>0.000423935026696007</mass>
               <inertia>
                  <ixx>2.65235443608576E-08</ixx>
                  <ixy>-1.09267072911845E-23</ixy>
                  <ixz>-1.65258864845697E-24</ixz>
                  <iyy>1.98779779728037E-07</iyy>
                  <iyz>4.05208227165849E-26</iyz>
                  <izz>2.25182852160328E-07</izz>
               </inertia>
            </inertial>
            <visual name="LW_Pitch">
               <pose relative_to="joint_LW_J_Pitch">0 0 0 0 0 0</pose>
               <geometry>
                  <mesh>
                     <uri>model://URDF_Tiny/meshes/LW_Pitch.STL</uri>
                  </mesh>
               </geometry>
               <material>
                  <ambient>0.0 1.0 0.0 .8</ambient>
                  <diffuse>0.0 1.0 0.0 .8</diffuse>
                  <specular>0.0 1.0 0.0 .75</specular>
               </material>
            </visual>
            <collision name="LW_Pitch">
               <pose relative_to="joint_LW_J_Pitch">0 0 0 0 0 0</pose>
               <geometry>
                  <mesh>
                     <uri>model://URDF_Tiny/meshes/LW_Pitch.STL</uri>
                  </mesh>
               </geometry>
               <material>
                  <ambient>0.0 1.0 0.0 .8</ambient>
                  <diffuse>0.0 1.0 0.0 .8</diffuse>
                  <specular>0.0 1.0 0.0 .75</specular>
               </material>
            </collision>
         </link>

         <joint name="joint_RW_J_Pitch" type="revolute">
            <pose relative_to="RW_Flap">0.00899999999999999 0.004 0 0 0 0</pose>
            <parent>RW_Flap</parent>
            <child>RW_Pitch</child>
            <axis>
               <xyz>-1 0 0</xyz>
               <dynamics>
                  <!-- <damping>.5</damping> -->
                  <!-- <friction>1</friction>    -->
                  <!-- <spring_reference>1.5708</spring_reference> -->
                  <spring_stiffness>.003</spring_stiffness>
               </dynamics>
               <limit>
                  <lower>-1.79769e+308</lower>
                  <upper>1.79769e+308</upper>
                  <!-- <lower>0</lower>
                  <upper>0</upper> -->
               </limit>
            </axis>
         </joint>

         <joint name="joint_LW_J_Pitch" type="revolute">
            <pose relative_to="LW_Flap">-0.00899999999999999 0.004 0 0 0 0</pose>
            <parent>LW_Flap</parent>
            <child>LW_Pitch</child>
            <axis>
               <xyz>1 0 0</xyz>
               <dynamics>
                  <!-- <damping>.5</damping> -->
                  <!-- <friction>1</friction>    -->
                  <!-- <spring_reference>1.5708</spring_reference> -->
                  <spring_stiffness>.003</spring_stiffness>
               </dynamics>
               <limit>
                  <lower>-1.79769e+308</lower>
                  <upper>1.79769e+308</upper>
                  <!-- <lower>0</lower>
                  <upper>0</upper> -->
               </limit>
            </axis>
         </joint>

         <joint name="joint_RW_J_Flap" type="revolute">
            <pose relative_to="base_link">0.00666143782776616 0 0 0 0 0</pose>
            <parent>base_link</parent>
            <child>RW_Flap</child>
            <axis>
               <xyz>0 -1 0</xyz>
               <dynamics>
                  <damping>.005</damping>
                  <!-- <friction>1</friction>    -->
                  <!-- <spring_reference>1.5708</spring_reference> -->
                  <spring_stiffness>.6</spring_stiffness>
               </dynamics>
               <limit>
                  <lower>-1.79769e+308</lower>
                  <upper>1.79769e+308</upper>
               </limit>
            </axis>
         </joint>

         <joint name="joint_LW_J_Flap" type="revolute">
            <pose relative_to="base_link">-0.00666143782776616 0 0 0 0 0</pose>
            <parent>base_link</parent>
            <child>LW_Flap</child>
            <axis>
               <xyz>0 -1 0</xyz>
               <dynamics>
                  <damping>.005</damping>
                  <!-- <friction>1</friction>    -->
                  <!-- <spring_reference>1.5708</spring_reference> -->
                  <spring_stiffness>.6</spring_stiffness>
               </dynamics>
               <limit>
                  <lower>-1.79769e+308</lower>
                  <upper>1.79769e+308</upper>
               </limit>
            </axis>
         </joint>

         <!-- hold model in air -->
         <joint name="anchor" type="revolute"> 
            <pose relative_to="base_link">0 0 0 0 0 0</pose>
            <parent>world</parent>
            <child>base_link</child>
            <axis>
               <xyz>0 0 1</xyz>
               <limit>
                  <lower>0</lower>
                  <upper>0</upper>
                  
               </limit>        
            </axis>
         </joint>

         <plugin filename="aero_state_plugins" name="aerodynamics">
            <data_file_path>/home/grasshopper/Github/ros2-gazebo-drake-sims/flapping_proj/data/aero.csv</data_file_path>
            <only_data>true</only_data>
            <link>
                <link_name>RW_Pitch</link_name>
                <link_type>wing</link_type>
                <stall_angle>15</stall_angle>
                <fluid_density>1.293</fluid_density>
                <drag_coefficient>1.28</drag_coefficient>
                <lift_coefficient>1</lift_coefficient>
                <control_joint>joint_RW_J_Flap</control_joint>
                <wing_pitch_joint>joint_RW_J_Pitch</wing_pitch_joint>
                <blades>15</blades>
                <center_pressure_list>-.0370,-0.007,0, -.0320,-0.007,0, -.0270,-0.007,0, -.0220,-0.007,0, -.0170,-0.007,0, -.0120,-0.007,0, -.0070,-0.007,0, -.002,-0.007,0, .0030,-0.007,0, .008,-0.007,0, .0130,-0.007,0, .0180,-0.007,0, .0230,-0.007,0, .0280,-0.007,0, .0330,-0.007,0 </center_pressure_list>
                <upward_vector_list>0,0,1, 0,0,1, 0,0,1, 0,0,1, 0,0,1, 0,0,1, 0,0,1, 0,0,1, 0,0,1, 0,0,1, 0,0,1, 0,0,1, 0,0,1, 0,0,1, 0,0,1 </upward_vector_list>
                <!-- <blade_area_list>0.0018</blade_area_list>  -->
                <blade_area_list>0.00012, 0.00012, 0.00012, 0.00012, 0.00012, 0.00012, 0.00012, 0.00012, 0.00012, 0.00012, 0.00012, 0.00012, 0.00012, 0.00012, 0.00012 </blade_area_list>
            </link>
            <link>
                <link_name>LW_Pitch</link_name>
                <link_type>wing</link_type>
                <stall_angle>15</stall_angle>
                <fluid_density>1.293</fluid_density>
                <drag_coefficient>1</drag_coefficient>
                <lift_coefficient>1</lift_coefficient>
                <control_joint>joint_LW_J_Flap</control_joint>
                <wing_pitch_joint>joint_LW_J_Pitch</wing_pitch_joint>
                <blades>15</blades>
                <!-- <center_pressure_list>0,0,0</center_pressure_list> -->
               <center_pressure_list>-.0370,-0.007,0, -.0320,-0.007,0, -.0270,-0.007,0, -.0220,-0.007,0, -.0170,-0.007,0, -.0120,-0.007,0, -.0070,-0.007,0, -.002,-0.007,0, .0030,-0.007,0, .008,-0.007,0, .0130,-0.007,0, .0180,-0.007,0, .0230,-0.007,0, .0280,-0.007,0, .0330,-0.007,0 </center_pressure_list>
                <!-- <upward_vector_list>0,0,1</upward_vector_list> -->
               <upward_vector_list>0,0,1, 0,0,1, 0,0,1, 0,0,1, 0,0,1, 0,0,1, 0,0,1, 0,0,1, 0,0,1, 0,0,1, 0,0,1, 0,0,1, 0,0,1, 0,0,1, 0,0,1 </upward_vector_list>
                <!-- <blade_area_list>0.0018</blade_area_list> -->
               <blade_area_list>0.00012, 0.00012, 0.00012, 0.00012, 0.00012, 0.00012, 0.00012, 0.00012, 0.00012, 0.00012, 0.00012, 0.00012, 0.00012, 0.00012, 0.00012 </blade_area_list>

            </link>
         </plugin>

         <!-- controller/odom plugin-->
         <plugin 
            filename="aero_state_plugins" 
            name="odometry_state">
            <world_name>world2</world_name>
            <odometry_topic>/odom</odometry_topic>
            <odom_publish_frequency>1000.0</odom_publish_frequency>
            <joint>joint_LW_J_Flap</joint> 
            <joint>joint_LW_J_Pitch</joint>
            <joint>joint_RW_J_Pitch</joint>
            <joint>joint_RW_J_Flap</joint>
         </plugin>

         <!-- subscribes to model_name/joint/jointname/cmd_force , takes doubles -->
         <!-- joints-->
         <!-- <plugin  
            filename="libignition-gazebo-apply-joint-force-system.so" 
            name = "ignition::gazebo::systems::ApplyJointForce">
            <joint_name>joint_LW_J_Pitch</joint_name>
         </plugin>
         <plugin  
            filename="libignition-gazebo-apply-joint-force-system.so" 
            name = "ignition::gazebo::systems::ApplyJointForce">
            <joint_name>joint_RW_J_Pitch</joint_name>
         </plugin> -->

         <!--wing links-->
         <plugin  
            filename="libignition-gazebo-apply-joint-force-system.so" 
            name = "ignition::gazebo::systems::ApplyJointForce">
            <joint_name>joint_LW_J_Flap</joint_name>
         </plugin>
         <plugin  
            filename="libignition-gazebo-apply-joint-force-system.so" 
            name = "ignition::gazebo::systems::ApplyJointForce">
         <joint_name>joint_RW_J_Flap</joint_name> 
         </plugin>

         <!-- <plugin
                filename="libignition-gazebo-diff-drive-system.so"
                name="ignition::gazebo::systems::DiffDrive">
                <left_joint>joint_LW_J_Flap</left_joint>
                <right_joint>joint_RW_J_Flap</right_joint>
                <wheel_separation>2</wheel_separation>
                <wheel_radius>0.4</wheel_radius>
                <topic>/world/diff_drive/cmd_vel</topic>
         </plugin> -->
      </model>
   </world>
</sdf>